Traceback (most recent call last):
  File "/Library/Frameworks/Python.framework/Versions/3.7/lib/python3.7/site-packages/jupyter_cache/executors/utils.py", line 56, in single_nb_execution
    record_timing=False,
  File "/Library/Frameworks/Python.framework/Versions/3.7/lib/python3.7/site-packages/nbclient/client.py", line 1093, in execute
    return NotebookClient(nb=nb, resources=resources, km=km, **kwargs).execute()
  File "/Library/Frameworks/Python.framework/Versions/3.7/lib/python3.7/site-packages/nbclient/util.py", line 84, in wrapped
    return just_run(coro(*args, **kwargs))
  File "/Library/Frameworks/Python.framework/Versions/3.7/lib/python3.7/site-packages/nbclient/util.py", line 62, in just_run
    return loop.run_until_complete(coro)
  File "/Library/Frameworks/Python.framework/Versions/3.7/lib/python3.7/asyncio/base_events.py", line 587, in run_until_complete
    return future.result()
  File "/Library/Frameworks/Python.framework/Versions/3.7/lib/python3.7/site-packages/nbclient/client.py", line 560, in async_execute
    cell, index, execution_count=self.code_cells_executed + 1
  File "/Library/Frameworks/Python.framework/Versions/3.7/lib/python3.7/site-packages/nbclient/client.py", line 854, in async_execute_cell
    self._check_raise_for_error(cell, exec_reply)
  File "/Library/Frameworks/Python.framework/Versions/3.7/lib/python3.7/site-packages/nbclient/client.py", line 756, in _check_raise_for_error
    raise CellExecutionError.from_cell_and_msg(cell, exec_reply_content)
nbclient.exceptions.CellExecutionError: An error occurred while executing the following cell:
------------------
df[2]['Capital']
------------------

[0;31m---------------------------------------------------------------------------[0m
[0;31mKeyError[0m                                  Traceback (most recent call last)
[0;32m/Library/Frameworks/Python.framework/Versions/3.7/lib/python3.7/site-packages/pandas/core/indexes/base.py[0m in [0;36mget_loc[0;34m(self, key, method, tolerance)[0m
[1;32m   3360[0m             [0;32mtry[0m[0;34m:[0m[0;34m[0m[0;34m[0m[0m
[0;32m-> 3361[0;31m                 [0;32mreturn[0m [0mself[0m[0;34m.[0m[0m_engine[0m[0;34m.[0m[0mget_loc[0m[0;34m([0m[0mcasted_key[0m[0;34m)[0m[0;34m[0m[0;34m[0m[0m
[0m[1;32m   3362[0m             [0;32mexcept[0m [0mKeyError[0m [0;32mas[0m [0merr[0m[0;34m:[0m[0;34m[0m[0;34m[0m[0m

[0;32m/Library/Frameworks/Python.framework/Versions/3.7/lib/python3.7/site-packages/pandas/_libs/index.pyx[0m in [0;36mpandas._libs.index.IndexEngine.get_loc[0;34m()[0m

[0;32m/Library/Frameworks/Python.framework/Versions/3.7/lib/python3.7/site-packages/pandas/_libs/index.pyx[0m in [0;36mpandas._libs.index.IndexEngine.get_loc[0;34m()[0m

[0;32mpandas/_libs/hashtable_class_helper.pxi[0m in [0;36mpandas._libs.hashtable.PyObjectHashTable.get_item[0;34m()[0m

[0;32mpandas/_libs/hashtable_class_helper.pxi[0m in [0;36mpandas._libs.hashtable.PyObjectHashTable.get_item[0;34m()[0m

[0;31mKeyError[0m: 2

The above exception was the direct cause of the following exception:

[0;31mKeyError[0m                                  Traceback (most recent call last)
[0;32m/var/folders/kl/h_r05n_j76n32kt0dwy7kynw0000gn/T/ipykernel_6505/4205149237.py[0m in [0;36m<module>[0;34m[0m
[0;32m----> 1[0;31m [0mdf[0m[0;34m[[0m[0;36m2[0m[0;34m][0m[0;34m[[0m[0;34m'Capital'[0m[0;34m][0m[0;34m[0m[0;34m[0m[0m
[0m
[0;32m/Library/Frameworks/Python.framework/Versions/3.7/lib/python3.7/site-packages/pandas/core/frame.py[0m in [0;36m__getitem__[0;34m(self, key)[0m
[1;32m   3456[0m             [0;32mif[0m [0mself[0m[0;34m.[0m[0mcolumns[0m[0;34m.[0m[0mnlevels[0m [0;34m>[0m [0;36m1[0m[0;34m:[0m[0;34m[0m[0;34m[0m[0m
[1;32m   3457[0m                 [0;32mreturn[0m [0mself[0m[0;34m.[0m[0m_getitem_multilevel[0m[0;34m([0m[0mkey[0m[0;34m)[0m[0;34m[0m[0;34m[0m[0m
[0;32m-> 3458[0;31m             [0mindexer[0m [0;34m=[0m [0mself[0m[0;34m.[0m[0mcolumns[0m[0;34m.[0m[0mget_loc[0m[0;34m([0m[0mkey[0m[0;34m)[0m[0;34m[0m[0;34m[0m[0m
[0m[1;32m   3459[0m             [0;32mif[0m [0mis_integer[0m[0;34m([0m[0mindexer[0m[0;34m)[0m[0;34m:[0m[0;34m[0m[0;34m[0m[0m
[1;32m   3460[0m                 [0mindexer[0m [0;34m=[0m [0;34m[[0m[0mindexer[0m[0;34m][0m[0;34m[0m[0;34m[0m[0m

[0;32m/Library/Frameworks/Python.framework/Versions/3.7/lib/python3.7/site-packages/pandas/core/indexes/base.py[0m in [0;36mget_loc[0;34m(self, key, method, tolerance)[0m
[1;32m   3361[0m                 [0;32mreturn[0m [0mself[0m[0;34m.[0m[0m_engine[0m[0;34m.[0m[0mget_loc[0m[0;34m([0m[0mcasted_key[0m[0;34m)[0m[0;34m[0m[0;34m[0m[0m
[1;32m   3362[0m             [0;32mexcept[0m [0mKeyError[0m [0;32mas[0m [0merr[0m[0;34m:[0m[0;34m[0m[0;34m[0m[0m
[0;32m-> 3363[0;31m                 [0;32mraise[0m [0mKeyError[0m[0;34m([0m[0mkey[0m[0;34m)[0m [0;32mfrom[0m [0merr[0m[0;34m[0m[0;34m[0m[0m
[0m[1;32m   3364[0m [0;34m[0m[0m
[1;32m   3365[0m         [0;32mif[0m [0mis_scalar[0m[0;34m([0m[0mkey[0m[0;34m)[0m [0;32mand[0m [0misna[0m[0;34m([0m[0mkey[0m[0;34m)[0m [0;32mand[0m [0;32mnot[0m [0mself[0m[0;34m.[0m[0mhasnans[0m[0;34m:[0m[0;34m[0m[0;34m[0m[0m

[0;31mKeyError[0m: 2
KeyError: 2

