Traceback (most recent call last):
  File "/Library/Frameworks/Python.framework/Versions/3.7/lib/python3.7/site-packages/jupyter_cache/executors/utils.py", line 56, in single_nb_execution
    record_timing=False,
  File "/Library/Frameworks/Python.framework/Versions/3.7/lib/python3.7/site-packages/nbclient/client.py", line 1093, in execute
    return NotebookClient(nb=nb, resources=resources, km=km, **kwargs).execute()
  File "/Library/Frameworks/Python.framework/Versions/3.7/lib/python3.7/site-packages/nbclient/util.py", line 84, in wrapped
    return just_run(coro(*args, **kwargs))
  File "/Library/Frameworks/Python.framework/Versions/3.7/lib/python3.7/site-packages/nbclient/util.py", line 62, in just_run
    return loop.run_until_complete(coro)
  File "/Library/Frameworks/Python.framework/Versions/3.7/lib/python3.7/asyncio/base_events.py", line 587, in run_until_complete
    return future.result()
  File "/Library/Frameworks/Python.framework/Versions/3.7/lib/python3.7/site-packages/nbclient/client.py", line 560, in async_execute
    cell, index, execution_count=self.code_cells_executed + 1
  File "/Library/Frameworks/Python.framework/Versions/3.7/lib/python3.7/site-packages/nbclient/client.py", line 854, in async_execute_cell
    self._check_raise_for_error(cell, exec_reply)
  File "/Library/Frameworks/Python.framework/Versions/3.7/lib/python3.7/site-packages/nbclient/client.py", line 756, in _check_raise_for_error
    raise CellExecutionError.from_cell_and_msg(cell, exec_reply_content)
nbclient.exceptions.CellExecutionError: An error occurred while executing the following cell:
------------------
# https://github.com/ofajardo/pyreadr#basic-usage--reading-files

result = pyreadr.read_r('/Users/Kaemyuijang/Documents/Github/pyreadr-master/test_data/basic/two.RData')

# done! let's see what we got
print(result.keys()) # let's check what objects we got
df1 = result["df1"] # extract the pandas data frame for object df1
------------------

[0;31m---------------------------------------------------------------------------[0m
[0;31mPyreadrError[0m                              Traceback (most recent call last)
[0;32m/var/folders/kl/h_r05n_j76n32kt0dwy7kynw0000gn/T/ipykernel_6263/2146603898.py[0m in [0;36m<module>[0;34m[0m
[1;32m      1[0m [0;31m# https://github.com/ofajardo/pyreadr#basic-usage--reading-files[0m[0;34m[0m[0;34m[0m[0;34m[0m[0m
[1;32m      2[0m [0;34m[0m[0m
[0;32m----> 3[0;31m [0mresult[0m [0;34m=[0m [0mpyreadr[0m[0;34m.[0m[0mread_r[0m[0;34m([0m[0;34m'/Users/Kaemyuijang/Documents/Github/pyreadr-master/test_data/basic/two.RData'[0m[0;34m)[0m[0;34m[0m[0;34m[0m[0m
[0m[1;32m      4[0m [0;34m[0m[0m
[1;32m      5[0m [0;31m# done! let's see what we got[0m[0;34m[0m[0;34m[0m[0;34m[0m[0m

[0;32m/Library/Frameworks/Python.framework/Versions/3.7/lib/python3.7/site-packages/pyreadr/pyreadr.py[0m in [0;36mread_r[0;34m(path, use_objects, timezone)[0m
[1;32m     63[0m     [0mfilename_bytes[0m [0;34m=[0m [0mos[0m[0;34m.[0m[0mpath[0m[0;34m.[0m[0mexpanduser[0m[0;34m([0m[0mfilename_bytes[0m[0;34m)[0m[0;34m[0m[0;34m[0m[0m
[1;32m     64[0m     [0;32mif[0m [0;32mnot[0m [0mos[0m[0;34m.[0m[0mpath[0m[0;34m.[0m[0misfile[0m[0;34m([0m[0mfilename_bytes[0m[0;34m)[0m[0;34m:[0m[0;34m[0m[0;34m[0m[0m
[0;32m---> 65[0;31m         [0;32mraise[0m [0mPyreadrError[0m[0;34m([0m[0;34m"File {0} does not exist!"[0m[0;34m.[0m[0mformat[0m[0;34m([0m[0mfilename_bytes[0m[0;34m)[0m[0;34m)[0m[0;34m[0m[0;34m[0m[0m
[0m[1;32m     66[0m     [0mparser[0m[0;34m.[0m[0mparse[0m[0;34m([0m[0mfilename_bytes[0m[0;34m)[0m[0;34m[0m[0;34m[0m[0m
[1;32m     67[0m [0;34m[0m[0m

[0;31mPyreadrError[0m: File b'/Users/Kaemyuijang/Documents/Github/pyreadr-master/test_data/basic/two.RData' does not exist!
PyreadrError: File b'/Users/Kaemyuijang/Documents/Github/pyreadr-master/test_data/basic/two.RData' does not exist!

