Traceback (most recent call last):
  File "/Library/Frameworks/Python.framework/Versions/3.7/lib/python3.7/site-packages/jupyter_cache/executors/utils.py", line 56, in single_nb_execution
    record_timing=False,
  File "/Library/Frameworks/Python.framework/Versions/3.7/lib/python3.7/site-packages/nbclient/client.py", line 1093, in execute
    return NotebookClient(nb=nb, resources=resources, km=km, **kwargs).execute()
  File "/Library/Frameworks/Python.framework/Versions/3.7/lib/python3.7/site-packages/nbclient/util.py", line 84, in wrapped
    return just_run(coro(*args, **kwargs))
  File "/Library/Frameworks/Python.framework/Versions/3.7/lib/python3.7/site-packages/nbclient/util.py", line 62, in just_run
    return loop.run_until_complete(coro)
  File "/Library/Frameworks/Python.framework/Versions/3.7/lib/python3.7/asyncio/base_events.py", line 587, in run_until_complete
    return future.result()
  File "/Library/Frameworks/Python.framework/Versions/3.7/lib/python3.7/site-packages/nbclient/client.py", line 560, in async_execute
    cell, index, execution_count=self.code_cells_executed + 1
  File "/Library/Frameworks/Python.framework/Versions/3.7/lib/python3.7/site-packages/nbclient/client.py", line 854, in async_execute_cell
    self._check_raise_for_error(cell, exec_reply)
  File "/Library/Frameworks/Python.framework/Versions/3.7/lib/python3.7/site-packages/nbclient/client.py", line 756, in _check_raise_for_error
    raise CellExecutionError.from_cell_and_msg(cell, exec_reply_content)
nbclient.exceptions.CellExecutionError: An error occurred while executing the following cell:
------------------
data = np.genfromtxt('6.overlap.csv', delimiter=',')
knn_comparision(data, 1)
knn_comparison(data, 5)
knn_comparison(data,15)
knn_comparison(data, 30)
knn_comparison(data, 50)

------------------

[0;31m---------------------------------------------------------------------------[0m
[0;31mNameError[0m                                 Traceback (most recent call last)
[0;32m/var/folders/kl/h_r05n_j76n32kt0dwy7kynw0000gn/T/ipykernel_5546/31344357.py[0m in [0;36m<module>[0;34m[0m
[1;32m      1[0m [0mdata[0m [0;34m=[0m [0mnp[0m[0;34m.[0m[0mgenfromtxt[0m[0;34m([0m[0;34m'6.overlap.csv'[0m[0;34m,[0m [0mdelimiter[0m[0;34m=[0m[0;34m','[0m[0;34m)[0m[0;34m[0m[0;34m[0m[0m
[0;32m----> 2[0;31m [0mknn_comparision[0m[0;34m([0m[0mdata[0m[0;34m,[0m [0;36m1[0m[0;34m)[0m[0;34m[0m[0;34m[0m[0m
[0m[1;32m      3[0m [0mknn_comparison[0m[0;34m([0m[0mdata[0m[0;34m,[0m [0;36m5[0m[0;34m)[0m[0;34m[0m[0;34m[0m[0m
[1;32m      4[0m [0mknn_comparison[0m[0;34m([0m[0mdata[0m[0;34m,[0m[0;36m15[0m[0;34m)[0m[0;34m[0m[0;34m[0m[0m
[1;32m      5[0m [0mknn_comparison[0m[0;34m([0m[0mdata[0m[0;34m,[0m [0;36m30[0m[0;34m)[0m[0;34m[0m[0;34m[0m[0m

[0;31mNameError[0m: name 'knn_comparision' is not defined
NameError: name 'knn_comparision' is not defined

